Workbook

Sheet Arrived Shipments
B1: Order Number | C1: Containers | D1: Bayan | E1: Shipment | F1: Supplier | G1: External Email | H1: Internal Email | I1: Transfer File sent? | J1: Transfer Qty Dispatched? | K1: Landing Cost | L1: Arrived | M1: Received | N1: Announcement Number | O1: PO | P1: Invoice | Q1: GRPO | R1: GRPO Date | S1: Days to be ready | T1: Sample Recieved ? | U1: Requested Date | V1: Recieved Date | W1: Prices updated in the system ? | X1: Remark | Y1: Shipment Status
A2: 1 | B2: =IFERROR(__xludf.DUMMYFUNCTION("INDEX(IMPORTRANGE(""https://docs.google.com/spreadsheets/d/1S7deMHO2waboU9dywpXeKIDfCmjiuAc0HUIsFpaXQq8/edit?gid=0#gid=0"", ""Tracking Shipments - PPTCO!o:o""), MATCH(D2, IMPORTRANGE(""https://docs.google.com/spreadsheets/d/1S7deMHO2waboU9dywpXeKIDfCmjiuA"&"c0HUIsFpaXQq8/edit?gid=0#gid=0"", ""Tracking Shipments - PPTCO!p:p""), 0))"),"PPT-73") -> PPT-73 | D2: 284599 | E2: JOSERA X9 | F2: Josera | G2: Before DSV | H2: Done | K2: Done | L2: Yes | M2: 45225 | N2: 0192023 | O2: 348 -> 358 | P2: 389 -> 399 | Q2: 348 -> 358 | R2: SMACC | S2: =IFERROR(IF(DATEDIF(M2,R2,"d")=0,"",DATEDIF(M2,R2,"d")),"") | T2: Not requested | W2: Done | Y2: Closed
A3: 2 | B3: =IFERROR(__xludf.DUMMYFUNCTION("INDEX(IMPORTRANGE(""https://docs.google.com/spreadsheets/d/1S7deMHO2waboU9dywpXeKIDfCmjiuAc0HUIsFpaXQq8/edit?gid=0#gid=0"", ""Tracking Shipments - PPTCO!o:o""), MATCH(D3, IMPORTRANGE(""https://docs.google.com/spreadsheets/d/1S7deMHO2waboU9dywpXeKIDfCmjiuA"&"c0HUIsFpaXQq8/edit?gid=0#gid=0"", ""Tracking Shipments - PPTCO!p:p""), 0))"),"PPT-29") -> PPT-29 | D3: 105972 | E3: KIT CAT - 400g | F3: Kit Cat | G3: Before DSV | H3: Done | K3: Done | L3: Yes | M3: 45236 | N3: 0192023 | O3: 361 | P3: 403 | Q3: 362 | R3: SMACC | S3: =IFERROR(IF(DATEDIF(M3,R3,"d")=0,"",DATEDIF(M3,R3,"d")),"") | T3: Received | W3: Done | Y3: Closed
A4: 3 | B4: =IFERROR(__xludf.DUMMYFUNCTION("INDEX(IMPORTRANGE(""https://docs.google.com/spreadsheets/d/1S7deMHO2waboU9dywpXeKIDfCmjiuAc0HUIsFpaXQq8/edit?gid=0#gid=0"", ""Tracking Shipments - PPTCO!o:o""), MATCH(D4, IMPORTRANGE(""https://docs.google.com/spreadsheets/d/1S7deMHO2waboU9dywpXeKIDfCmjiuA"&"c0HUIsFpaXQq8/edit?gid=0#gid=0"", ""Tracking Shipments - PPTCO!p:p""), 0))"),"PUUR ") -> PUUR | D4: 300854 | E4: LAROY - PUUR | F4: Laroy | G4: Before DSV | H4: Done | K4: Done | L4: Yes | M4: 45229 | N4: 212023 | O4: 359 | P4: 401 | Q4: 360 | R4: SMACC | S4: =IFERROR(IF(DATEDIF(M4,R4,"d")=0,"",DATEDIF(M4,R4,"d")),"") | W4: Done | Y4: Closed
A5: 4 | B5: =IFERROR(__xludf.DUMMYFUNCTION("INDEX(IMPORTRANGE(""https://docs.google.com/spreadsheets/d/1S7deMHO2waboU9dywpXeKIDfCmjiuAc0HUIsFpaXQq8/edit?gid=0#gid=0"", ""Tracking Shipments - PPTCO!o:o""), MATCH(D5, IMPORTRANGE(""https://docs.google.com/spreadsheets/d/1S7deMHO2waboU9dywpXeKIDfCmjiuA"&"c0HUIsFpaXQq8/edit?gid=0#gid=0"", ""Tracking Shipments - PPTCO!p:p""), 0))"),"PPT-39") -> PPT-39 | D5: 90377 | E5: KIT CAT - KCIT230042B/2-C | F5: Kit Cat | G5: Before DSV | H5: Done | K5: Done | L5: Yes | M5: 45200 | N5: 212023 | O5: 360 | P5: 400 | Q5: 361 | R5: SMACC | S5: =IFERROR(IF(DATEDIF(M5,R5,"d")=0,"",DATEDIF(M5,R5,"d")),"") | Y5: Closed
A6: 5 | B6: =IFERROR(__xludf.DUMMYFUNCTION("INDEX(IMPORTRANGE(""https://docs.google.com/spreadsheets/d/1S7deMHO2waboU9dywpXeKIDfCmjiuAc0HUIsFpaXQq8/edit?gid=0#gid=0"", ""Tracking Shipments - PPTCO!o:o""), MATCH(D6, IMPORTRANGE(""https://docs.google.com/spreadsheets/d/1S7deMHO2waboU9dywpXeKIDfCmjiuA"&"c0HUIsFpaXQq8/edit?gid=0#gid=0"", ""Tracking Shipments - PPTCO!p:p""), 0))"),"PPT-51") -> PPT-51 | D6: 101368 | E6: SCHESIR - 901104 | F6: Schesir | G6: Before DSV | H6: Done | K6: Done | L6: Yes | M6: 45225 | N6: 0192023 | O6: 347 | P6: 388 | Q6: 347 | R6: SMACC | S6: =IFERROR(IF(DATEDIF(M6,R6,"d")=0,"",DATEDIF(M6,R6,"d")),"") | Y6: Closed
A7: 6 | B7: =IFERROR(__xludf.DUMMYFUNCTION("INDEX(IMPORTRANGE(""https://docs.google.com/spreadsheets/d/1S7deMHO2waboU9dywpXeKIDfCmjiuAc0HUIsFpaXQq8/edit?gid=0#gid=0"", ""Tracking Shipments - PPTCO!o:o""), MATCH(D7, IMPORTRANGE(""https://docs.google.com/spreadsheets/d/1S7deMHO2waboU9dywpXeKIDfCmjiuA"&"c0HUIsFpaXQq8/edit?gid=0#gid=0"", ""Tracking Shipments - PPTCO!p:p""), 0))"),"PPT-51") -> PPT-51 | D7: 101362 | E7: SCHESIR - 901105 | F7: Schesir | G7: Before DSV | H7: Done | K7: Done | L7: Yes | M7: 45225 | N7: 0192023 | O7: 346 | P7: 387 | Q7: 359 | R7: SMACC | S7: =IFERROR(IF(DATEDIF(M7,R7,"d")=0,"",DATEDIF(M7,R7,"d")),"") | Y7: Closed
A8: 7 | B8: =IFERROR(__xludf.DUMMYFUNCTION("INDEX(IMPORTRANGE(""https://docs.google.com/spreadsheets/d/1S7deMHO2waboU9dywpXeKIDfCmjiuAc0HUIsFpaXQq8/edit?gid=0#gid=0"", ""Tracking Shipments - PPTCO!o:o""), MATCH(D8, IMPORTRANGE(""https://docs.google.com/spreadsheets/d/1S7deMHO2waboU9dywpXeKIDfCmjiuA"&"c0HUIsFpaXQq8/edit?gid=0#gid=0"", ""Tracking Shipments - PPTCO!p:p""), 0))"),"PUUR ") -> PUUR | D8: 306682 | E8: LAROY - PUUR | F8: Laroy | G8: Before DSV | H8: Done | K8: Done | L8: Yes | M8: 45241 | N8: 212023 | O8: 363->365 | P8: 408->410 | Q8: 364->366 | R8: SMACC | S8: =IFERROR(IF(DATEDIF(M8,R8,"d")=0,"",DATEDIF(M8,R8,"d")),"") | W8: Done | Y8: Closed
A9: 8 | B9: =IFERROR(__xludf.DUMMYFUNCTION("INDEX(IMPORTRANGE(""https://docs.google.com/spreadsheets/d/1S7deMHO2waboU9dywpXeKIDfCmjiuAc0HUIsFpaXQq8/edit?gid=0#gid=0"", ""Tracking Shipments - PPTCO!o:o""), MATCH(D9, IMPORTRANGE(""https://docs.google.com/spreadsheets/d/1S7deMHO2waboU9dywpXeKIDfCmjiuA"&"c0HUIsFpaXQq8/edit?gid=0#gid=0"", ""Tracking Shipments - PPTCO!p:p""), 0))"),"N/A") -> N/A | D9: 104096 | E9: INNER MONGOLIA | F9: Inner Mongolia | G9: Before DSV | H9: Done | K9: Done | L9: Yes | M9: 45238 | N9: 212023 | O9: 366-> 369 | P9: 411 > 412 | Q9: 367-> 370 | R9: SMACC | S9: =IFERROR(IF(DATEDIF(M9,R9,"d")=0,"",DATEDIF(M9,R9,"d")),"") | W9: Done | Y9: Closed
A10: 9 | B10: =IFERROR(__xludf.DUMMYFUNCTION("INDEX(IMPORTRANGE(""https://docs.google.com/spreadsheets/d/1S7deMHO2waboU9dywpXeKIDfCmjiuAc0HUIsFpaXQq8/edit?gid=0#gid=0"", ""Tracking Shipments - PPTCO!o:o""), MATCH(D10, IMPORTRANGE(""https://docs.google.com/spreadsheets/d/1S7deMHO2waboU9dywpXeKIDfCmjiu"&"Ac0HUIsFpaXQq8/edit?gid=0#gid=0"", ""Tracking Shipments - PPTCO!p:p""), 0))"),"PPT-58") -> PPT-58 | D10: 106546 | E10: KCIT230134 - Yogurt | F10: Kit Cat | G10: Before DSV | H10: Done | K10: Done | L10: Yes | M10: 45241 | N10: 212023 | O10: 362 | P10: 407 | Q10: 363 | R10: SMACC | S10: =IFERROR(IF(DATEDIF(M10,R10,"d")=0,"",DATEDIF(M10,R10,"d")),"") | W10: Done | Y10: Closed
A11: 10 | B11: =IFERROR(__xludf.DUMMYFUNCTION("INDEX(IMPORTRANGE(""https://docs.google.com/spreadsheets/d/1S7deMHO2waboU9dywpXeKIDfCmjiuAc0HUIsFpaXQq8/edit?gid=0#gid=0"", ""Tracking Shipments - PPTCO!o:o""), MATCH(D11, IMPORTRANGE(""https://docs.google.com/spreadsheets/d/1S7deMHO2waboU9dywpXeKIDfCmjiu"&"Ac0HUIsFpaXQq8/edit?gid=0#gid=0"", ""Tracking Shipments - PPTCO!p:p""), 0))"),"SA001-2023") -> SA001-2023 | D11: 115808 | E11: INABA | F11: INABA | G11: Before DSV | H11: Done | K11: Done | L11: Yes | M11: 45270 | N11: 232023 | O11: 374-375 | P11: 418-419 | Q11: 375-376 | R11: SMACC | S11: =IFERROR(IF(DATEDIF(M11,R11,"d")=0,"",DATEDIF(M11,R11,"d")),"") | W11: Done | Y11: Closed
A12: 11 | B12: =IFERROR(__xludf.DUMMYFUNCTION("INDEX(IMPORTRANGE(""https://docs.google.com/spreadsheets/d/1S7deMHO2waboU9dywpXeKIDfCmjiuAc0HUIsFpaXQq8/edit?gid=0#gid=0"", ""Tracking Shipments - PPTCO!o:o""), MATCH(D12, IMPORTRANGE(""https://docs.google.com/spreadsheets/d/1S7deMHO2waboU9dywpXeKIDfCmjiu"&"Ac0HUIsFpaXQq8/edit?gid=0#gid=0"", ""Tracking Shipments - PPTCO!p:p""), 0))"),"PPT-78") -> PPT-78 | D12: 115809 | E12: SANAL/NEDARMA | F12: Sanal | G12: Before DSV | H12: Done | K12: Done | L12: Yes | M12: 45265 | N12: 232023 | O12: 370 | P12: 417 | Q12: 371 | R12: SMACC | S12: =IFERROR(IF(DATEDIF(M12,R12,"d")=0,"",DATEDIF(M12,R12,"d")),"") | Y12: Closed
A13: 12 | B13: =IFERROR(__xludf.DUMMYFUNCTION("INDEX(IMPORTRANGE(""https://docs.google.com/spreadsheets/d/1S7deMHO2waboU9dywpXeKIDfCmjiuAc0HUIsFpaXQq8/edit?gid=0#gid=0"", ""Tracking Shipments - PPTCO!o:o""), MATCH(D13, IMPORTRANGE(""https://docs.google.com/spreadsheets/d/1S7deMHO2waboU9dywpXeKIDfCmjiu"&"Ac0HUIsFpaXQq8/edit?gid=0#gid=0"", ""Tracking Shipments - PPTCO!p:p""), 0))"),"PPT-75") -> PPT-75 | D13: 108588 | E13: Schesir -901280 | F13: Schesir | G13: Before DSV | H13: Done | K13: Done | L13: Yes | M13: 45248 | N13: 212023 | O13: 367 | P13: 414 | Q13: 368 | R13: SMACC | S13: =IFERROR(IF(DATEDIF(M13,R13,"d")=0,"",DATEDIF(M13,R13,"d")),"") | W13: Done | X13: Moayad Pricing | Y13: Closed
A14: 13 | B14: =IFERROR(__xludf.DUMMYFUNCTION("INDEX(IMPORTRANGE(""https://docs.google.com/spreadsheets/d/1S7deMHO2waboU9dywpXeKIDfCmjiuAc0HUIsFpaXQq8/edit?gid=0#gid=0"", ""Tracking Shipments - PPTCO!o:o""), MATCH(D14, IMPORTRANGE(""https://docs.google.com/spreadsheets/d/1S7deMHO2waboU9dywpXeKIDfCmjiu"&"Ac0HUIsFpaXQq8/edit?gid=0#gid=0"", ""Tracking Shipments - PPTCO!p:p""), 0))"),"N/A") -> N/A | D14: 108586 | E14: Schesir -901281 | F14: Schesir | G14: Before DSV | H14: Done | K14: Done | L14: Yes | M14: 44907 | N14: 212023 | O14: 368 | P14: 413 | Q14: 369 | R14: SMACC | S14: =IFERROR(IF(DATEDIF(M14,R14,"d")=0,"",DATEDIF(M14,R14,"d")),"") | W14: Done | X14: Moayad Pricing | Y14: Closed
A15: 14 | B15: =IFERROR(__xludf.DUMMYFUNCTION("INDEX(IMPORTRANGE(""https://docs.google.com/spreadsheets/d/1S7deMHO2waboU9dywpXeKIDfCmjiuAc0HUIsFpaXQq8/edit?gid=0#gid=0"", ""Tracking Shipments - PPTCO!o:o""), MATCH(D15, IMPORTRANGE(""https://docs.google.com/spreadsheets/d/1S7deMHO2waboU9dywpXeKIDfCmjiu"&"Ac0HUIsFpaXQq8/edit?gid=0#gid=0"", ""Tracking Shipments - PPTCO!p:p""), 0))"),"PPT-83") -> PPT-83 | D15: 341926 | E15: Witte Molen Expert | F15: Laroy | G15: Before DSV | H15: Done | K15: Done | L15: Yes | M15: 45270 | N15: 232023 | O15: 371 > 373 | P15: 420 > 422 | Q15: 372 > 374 | R15: SMACC | S15: =IFERROR(IF(DATEDIF(M15,R15,"d")=0,"",DATEDIF(M15,R15,"d")),"") | W15: Done | Y15: Closed
A16: 15 | B16: =IFERROR(__xludf.DUMMYFUNCTION("INDEX(IMPORTRANGE(""https://docs.google.com/spreadsheets/d/1S7deMHO2waboU9dywpXeKIDfCmjiuAc0HUIsFpaXQq8/edit?gid=0#gid=0"", ""Tracking Shipments - PPTCO!o:o""), MATCH(D16, IMPORTRANGE(""https://docs.google.com/spreadsheets/d/1S7deMHO2waboU9dywpXeKIDfCmjiu"&"Ac0HUIsFpaXQq8/edit?gid=0#gid=0"", ""Tracking Shipments - PPTCO!p:p""), 0))"),"N/A") -> N/A | D16: 117571 | E16: BUTCHERS | F16: Butchers | G16: Before DSV | H16: Done | K16: Done | L16: Yes | M16: 45273 | N16: 232023 | O16: 376-377 | P16: 423 - 424 | Q16: 377-378 | R16: SMACC | S16: =IFERROR(IF(DATEDIF(M16,R16,"d")=0,"",DATEDIF(M16,R16,"d")),"") | Y16: Closed
A17: 16 | B17: =IFERROR(__xludf.DUMMYFUNCTION("INDEX(IMPORTRANGE(""https://docs.google.com/spreadsheets/d/1S7deMHO2waboU9dywpXeKIDfCmjiuAc0HUIsFpaXQq8/edit?gid=0#gid=0"", ""Tracking Shipments - PPTCO!o:o""), MATCH(D17, IMPORTRANGE(""https://docs.google.com/spreadsheets/d/1S7deMHO2waboU9dywpXeKIDfCmjiu"&"Ac0HUIsFpaXQq8/edit?gid=0#gid=0"", ""Tracking Shipments - PPTCO!p:p""), 0))"),"PPT-39") -> PPT-39 | D17: 119664 | E17: KIT CAT -Deboned 42A | F17: Kit Cat | G17: Before DSV | H17: Done | K17: Done | L17: Yes | M17: 45281 | N17: 242023 | O17: 385 | P17: 431 | Q17: 386 | R17: SMACC | S17: =IFERROR(IF(DATEDIF(M17,R17,"d")=0,"",DATEDIF(M17,R17,"d")),"") | W17: Done | Y17: Closed
A18: 17 | B18: =IFERROR(__xludf.DUMMYFUNCTION("INDEX(IMPORTRANGE(""https://docs.google.com/spreadsheets/d/1S7deMHO2waboU9dywpXeKIDfCmjiuAc0HUIsFpaXQq8/edit?gid=0#gid=0"", ""Tracking Shipments - PPTCO!o:o""), MATCH(D18, IMPORTRANGE(""https://docs.google.com/spreadsheets/d/1S7deMHO2waboU9dywpXeKIDfCmjiu"&"Ac0HUIsFpaXQq8/edit?gid=0#gid=0"", ""Tracking Shipments - PPTCO!p:p""), 0))"),"PPT-34") -> PPT-34 | D18: 120610 | E18: KIT CAT - Deboned 45 | F18: Kit Cat | G18: Before DSV | H18: Done | K18: Done | L18: Yes | M18: 45280 | N18: 242023 | O18: 383 | P18: 426 | Q18: 384 | R18: SMACC | S18: =IFERROR(IF(DATEDIF(M18,R18,"d")=0,"",DATEDIF(M18,R18,"d")),"") | W18: Done | Y18: Closed
A19: 18 | B19: =IFERROR(__xludf.DUMMYFUNCTION("INDEX(IMPORTRANGE(""https://docs.google.com/spreadsheets/d/1S7deMHO2waboU9dywpXeKIDfCmjiuAc0HUIsFpaXQq8/edit?gid=0#gid=0"", ""Tracking Shipments - PPTCO!o:o""), MATCH(D19, IMPORTRANGE(""https://docs.google.com/spreadsheets/d/1S7deMHO2waboU9dywpXeKIDfCmjiu"&"Ac0HUIsFpaXQq8/edit?gid=0#gid=0"", ""Tracking Shipments - PPTCO!p:p""), 0))"),"N/A") -> N/A | D19: 117571 | E19: Butcher's FS/23/10/0001/EX, FS/23/10/0002/EX | F19: Butchers | G19: Before DSV | H19: Done | K19: Done | L19: Yes | M19: 45273 | N19: 242023 | O19: 386 - 387 | P19: 436 - 437 | Q19: 387 - 388 | R19: SMACC | S19: =IFERROR(IF(DATEDIF(M19,R19,"d")=0,"",DATEDIF(M19,R19,"d")),"") | W19: Done | Y19: Closed
A20: 19 | B20: =IFERROR(__xludf.DUMMYFUNCTION("INDEX(IMPORTRANGE(""https://docs.google.com/spreadsheets/d/1S7deMHO2waboU9dywpXeKIDfCmjiuAc0HUIsFpaXQq8/edit?gid=0#gid=0"", ""Tracking Shipments - PPTCO!o:o""), MATCH(D20, IMPORTRANGE(""https://docs.google.com/spreadsheets/d/1S7deMHO2waboU9dywpXeKIDfCmjiu"&"Ac0HUIsFpaXQq8/edit?gid=0#gid=0"", ""Tracking Shipments - PPTCO!p:p""), 0))"),"PPT-39") -> PPT-39 | D20: 124051 | E20: KIT CAT - Goat Milk | F20: Kit Cat | G20: Before DSV | H20: Done | K20: Done | L20: Yes | M20: 45293 | N20: 242023 | O20: 394 | P20: 439 | Q20: 395 | R20: SMACC | S20: =IFERROR(IF(DATEDIF(M20,R20,"d")=0,"",DATEDIF(M20,R20,"d")),"") | W20: Done | Y20: Closed
A21: 20 | B21: =IFERROR(__xludf.DUMMYFUNCTION("INDEX(IMPORTRANGE(""https://docs.google.com/spreadsheets/d/1S7deMHO2waboU9dywpXeKIDfCmjiuAc0HUIsFpaXQq8/edit?gid=0#gid=0"", ""Tracking Shipments - PPTCO!o:o""), MATCH(D21, IMPORTRANGE(""https://docs.google.com/spreadsheets/d/1S7deMHO2waboU9dywpXeKIDfCmjiu"&"Ac0HUIsFpaXQq8/edit?gid=0#gid=0"", ""Tracking Shipments - PPTCO!p:p""), 0))"),"PPT-35") -> PPT-35 | D21: 124042 | E21: KIT CAT - Gravy | F21: Kit Cat | G21: Before DSV | H21: Done | K21: Done | L21: Yes | M21: 45293 | N21: 242023 | O21: 395 | P21: 440 | Q21: 396 | R21: SMACC | S21: =IFERROR(IF(DATEDIF(M21,R21,"d")=0,"",DATEDIF(M21,R21,"d")),"") | W21: Done | Y21: Closed
A22: 21 | B22: =IFERROR(__xludf.DUMMYFUNCTION("INDEX(IMPORTRANGE(""https://docs.google.com/spreadsheets/d/1S7deMHO2waboU9dywpXeKIDfCmjiuAc0HUIsFpaXQq8/edit?gid=0#gid=0"", ""Tracking Shipments - PPTCO!o:o""), MATCH(D22, IMPORTRANGE(""https://docs.google.com/spreadsheets/d/1S7deMHO2waboU9dywpXeKIDfCmjiu"&"Ac0HUIsFpaXQq8/edit?gid=0#gid=0"", ""Tracking Shipments - PPTCO!p:p""), 0))"),"PPT-71") -> PPT-71 | D22: 349863 | E22: Applaws Cat Dry "4 Contenr | F22: Applaws | G22: Before DSV | H22: Done | K22: Done | L22: Yes | M22: 45278 | N22: 242023 | O22: 378 > 381 | P22: 427 > 430 | Q22: 379 > 382 | R22: SMACC | S22: =IFERROR(IF(DATEDIF(M22,R22,"d")=0,"",DATEDIF(M22,R22,"d")),"") | W22: Done | Y22: Closed
A23: 22 | B23: =IFERROR(__xludf.DUMMYFUNCTION("INDEX(IMPORTRANGE(""https://docs.google.com/spreadsheets/d/1S7deMHO2waboU9dywpXeKIDfCmjiuAc0HUIsFpaXQq8/edit?gid=0#gid=0"", ""Tracking Shipments - PPTCO!o:o""), MATCH(D23, IMPORTRANGE(""https://docs.google.com/spreadsheets/d/1S7deMHO2waboU9dywpXeKIDfCmjiu"&"Ac0HUIsFpaXQq8/edit?gid=0#gid=0"", ""Tracking Shipments - PPTCO!p:p""), 0))"),"PPT-71") -> PPT-71 | D23: 353778 | E23: Applaws Cat Dry "6 Contenr | F23: Applaws | G23: Before DSV | H23: Done | K23: Done | L23: Yes | M23: 45291 | N23: 242023 | O23: 388 < 393 | P23: 441 > 446 | Q23: 389 < 394 | R23: SMACC | S23: =IFERROR(IF(DATEDIF(M23,R23,"d")=0,"",DATEDIF(M23,R23,"d")),"") | W23: Done | Y23: Closed
A24: 23 | B24: =IFERROR(__xludf.DUMMYFUNCTION("INDEX(IMPORTRANGE(""https://docs.google.com/spreadsheets/d/1S7deMHO2waboU9dywpXeKIDfCmjiuAc0HUIsFpaXQq8/edit?gid=0#gid=0"", ""Tracking Shipments - PPTCO!o:o""), MATCH(D24, IMPORTRANGE(""https://docs.google.com/spreadsheets/d/1S7deMHO2waboU9dywpXeKIDfCmjiu"&"Ac0HUIsFpaXQq8/edit?gid=0#gid=0"", ""Tracking Shipments - PPTCO!p:p""), 0))"),"PPT-65") -> PPT-65 | D24: 657 | E24: CATIDEA | F24: CatIdea | G24: Before DSV | H24: Done | K24: Done | L24: Yes | M24: 45300 | N24: 242023 | O24: 4 | P24: 2 | Q24: 10 | R24: 45328 | S24: =IFERROR(IF(DATEDIF(M24,R24,"d")=0,"",DATEDIF(M24,R24,"d")),"") -> 28 | W24: Done | Y24: Closed
A25: 24 | B25: =IFERROR(__xludf.DUMMYFUNCTION("INDEX(IMPORTRANGE(""https://docs.google.com/spreadsheets/d/1S7deMHO2waboU9dywpXeKIDfCmjiuAc0HUIsFpaXQq8/edit?gid=0#gid=0"", ""Tracking Shipments - PPTCO!o:o""), MATCH(D25, IMPORTRANGE(""https://docs.google.com/spreadsheets/d/1S7deMHO2waboU9dywpXeKIDfCmjiu"&"Ac0HUIsFpaXQq8/edit?gid=0#gid=0"", ""Tracking Shipments - PPTCO!p:p""), 0))"),"#N/A") -> #N/A | D25: 236554 | E25: My Family 8406 | F25: MyFamily | G25: Before DSV | H25: Done | K25: Done | L25: Yes | M25: 45277 | O25: 384 | P25: 438 | Q25: 385 | R25: SMACC | S25: =IFERROR(IF(DATEDIF(M25,R25,"d")=0,"",DATEDIF(M25,R25,"d")),"") | W25: Done | Y25: Closed
A26: 25 | B26: =IFERROR(__xludf.DUMMYFUNCTION("INDEX(IMPORTRANGE(""https://docs.google.com/spreadsheets/d/1S7deMHO2waboU9dywpXeKIDfCmjiuAc0HUIsFpaXQq8/edit?gid=0#gid=0"", ""Tracking Shipments - PPTCO!o:o""), MATCH(D26, IMPORTRANGE(""https://docs.google.com/spreadsheets/d/1S7deMHO2waboU9dywpXeKIDfCmjiu"&"Ac0HUIsFpaXQq8/edit?gid=0#gid=0"", ""Tracking Shipments - PPTCO!p:p""), 0))"),"#N/A") -> #N/A | E26: LAYROY Expert 313+314+315 | F26: Laroy | G26: Before DSV | H26: Done | O26: 131-133 | P26: 498-500 | Q26: 127-129 | S26: =IFERROR(IF(DATEDIF(M26,R26,"d")=0,"",DATEDIF(M26,R26,"d")),"") | Y26: Closed
A27: 26 | B27: =IFERROR(__xludf.DUMMYFUNCTION("INDEX(IMPORTRANGE(""https://docs.google.com/spreadsheets/d/1S7deMHO2waboU9dywpXeKIDfCmjiuAc0HUIsFpaXQq8/edit?gid=0#gid=0"", ""Tracking Shipments - PPTCO!o:o""), MATCH(D27, IMPORTRANGE(""https://docs.google.com/spreadsheets/d/1S7deMHO2waboU9dywpXeKIDfCmjiu"&"Ac0HUIsFpaXQq8/edit?gid=0#gid=0"", ""Tracking Shipments - PPTCO!p:p""), 0))"),"#N/A") -> #N/A | D27: 2702 | E27: Kit Cat SoyaClump KCIT230322 | F27: Kit Cat | G27: Before DSV | H27: Done | K27: Done | L27: Yes | M27: 45302 | N27: 0012024 | O27: 16 | P27: 7 | Q27: 2 | R27: 45328 | S27: =IFERROR(IF(DATEDIF(M27,R27,"d")=0,"",DATEDIF(M27,R27,"d")),"") -> 26 | Y27: Closed
A28: 27 | B28: =IFERROR(__xludf.DUMMYFUNCTION("INDEX(IMPORTRANGE(""https://docs.google.com/spreadsheets/d/1S7deMHO2waboU9dywpXeKIDfCmjiuAc0HUIsFpaXQq8/edit?gid=0#gid=0"", ""Tracking Shipments - PPTCO!o:o""), MATCH(D28, IMPORTRANGE(""https://docs.google.com/spreadsheets/d/1S7deMHO2waboU9dywpXeKIDfCmjiu"&"Ac0HUIsFpaXQq8/edit?gid=0#gid=0"", ""Tracking Shipments - PPTCO!p:p""), 0))"),"PPT-67") -> PPT-67 | D28: 15674 | E28: VERSELE LAGA 2311826 | F28: Versele Laga | G28: Before DSV | H28: Done | K28: Done | L28: Yes | M28: 45325 | N28: 0012024 | O28: 22 | P28: 23 | Q28: 21 | R28: 45329 | S28: =IFERROR(IF(DATEDIF(M28,R28,"d")=0,"",DATEDIF(M28,R28,"d")),"") -> 4 | Y28: Closed
A29: 28 | B29: =IFERROR(__xludf.DUMMYFUNCTION("INDEX(IMPORTRANGE(""https://docs.google.com/spreadsheets/d/1S7deMHO2waboU9dywpXeKIDfCmjiuAc0HUIsFpaXQq8/edit?gid=0#gid=0"", ""Tracking Shipments - PPTCO!o:o""), MATCH(D29, IMPORTRANGE(""https://docs.google.com/spreadsheets/d/1S7deMHO2waboU9dywpXeKIDfCmjiu"&"Ac0HUIsFpaXQq8/edit?gid=0#gid=0"", ""Tracking Shipments - PPTCO!p:p""), 0))"),"PPT-67") -> PPT-67 | D29: 15129 | E29: VERSELE LAGA 2311821 , 2311822 | F29: Versele Laga | G29: Before DSV | H29: Done | K29: Done | L29: Yes | M29: 45325 | N29: 0012024 | O29: 20 , 21 | P29: 20 , 21 | Q29: 22 , 23 | R29: 45329 | S29: =IFERROR(IF(DATEDIF(M29,R29,"d")=0,"",DATEDIF(M29,R29,"d")),"") -> 4 | Y29: Closed
A30: 29 | B30: =IFERROR(__xludf.DUMMYFUNCTION("INDEX(IMPORTRANGE(""https://docs.google.com/spreadsheets/d/1S7deMHO2waboU9dywpXeKIDfCmjiuAc0HUIsFpaXQq8/edit?gid=0#gid=0"", ""Tracking Shipments - PPTCO!o:o""), MATCH(D30, IMPORTRANGE(""https://docs.google.com/spreadsheets/d/1S7deMHO2waboU9dywpXeKIDfCmjiu"&"Ac0HUIsFpaXQq8/edit?gid=0#gid=0"", ""Tracking Shipments - PPTCO!p:p""), 0))"),"PPT-80") -> PPT-80 | D30: 10114 | E30: LAVIOSA 2300000541 | F30: Laviosa | G30: Before DSV | H30: Done | K30: Done | L30: Yes | M30: 45309 | N30: 0012024 | O30: 3 | P30: 12 | Q30: 14 | R30: 45328 | S30: =IFERROR(IF(DATEDIF(M30,R30,"d")=0,"",DATEDIF(M30,R30,"d")),"") -> 19 | Y30: Closed
A31: 30 | B31: =IFERROR(__xludf.DUMMYFUNCTION("INDEX(IMPORTRANGE(""https://docs.google.com/spreadsheets/d/1S7deMHO2waboU9dywpXeKIDfCmjiuAc0HUIsFpaXQq8/edit?gid=0#gid=0"", ""Tracking Shipments - PPTCO!o:o""), MATCH(D31, IMPORTRANGE(""https://docs.google.com/spreadsheets/d/1S7deMHO2waboU9dywpXeKIDfCmjiu"&"Ac0HUIsFpaXQq8/edit?gid=0#gid=0"", ""Tracking Shipments - PPTCO!p:p""), 0))"),"PPT-83") -> PPT-83 | D31: 15125 | E31: LAYROY 513 +765+ 766 | F31: Laroy | G31: Before DSV | H31: Done | K31: Done | L31: Yes | M31: 45325 | N31: 0012024 | O31: 10 -> 12 | P31: 3 -> 5 | Q31: 5 -> 7 | R31: 45328 | S31: =IFERROR(IF(DATEDIF(M31,R31,"d")=0,"",DATEDIF(M31,R31,"d")),"") -> 3 | Y31: Closed
A32: 31 | B32: =IFERROR(__xludf.DUMMYFUNCTION("INDEX(IMPORTRANGE(""https://docs.google.com/spreadsheets/d/1S7deMHO2waboU9dywpXeKIDfCmjiuAc0HUIsFpaXQq8/edit?gid=0#gid=0"", ""Tracking Shipments - PPTCO!o:o""), MATCH(D32, IMPORTRANGE(""https://docs.google.com/spreadsheets/d/1S7deMHO2waboU9dywpXeKIDfCmjiu"&"Ac0HUIsFpaXQq8/edit?gid=0#gid=0"", ""Tracking Shipments - PPTCO!p:p""), 0))"),"PPT-80") -> PPT-80 | D32: 10121 | E32: LAVIOSA 2300000548 - 2300000563 | F32: Laviosa | G32: Before DSV | H32: Done | K32: Done | L32: Yes | M32: 45309 | N32: 0012024 | O32: 7 , 8 | P32: 13 , 14 | Q32: 11 , 12 | R32: 45328 | S32: =IFERROR(IF(DATEDIF(M32,R32,"d")=0,"",DATEDIF(M32,R32,"d")),"") -> 19 | Y32: Closed
A33: 32 | B33: =IFERROR(__xludf.DUMMYFUNCTION("INDEX(IMPORTRANGE(""https://docs.google.com/spreadsheets/d/1S7deMHO2waboU9dywpXeKIDfCmjiuAc0HUIsFpaXQq8/edit?gid=0#gid=0"", ""Tracking Shipments - PPTCO!o:o""), MATCH(D33, IMPORTRANGE(""https://docs.google.com/spreadsheets/d/1S7deMHO2waboU9dywpXeKIDfCmjiu"&"Ac0HUIsFpaXQq8/edit?gid=0#gid=0"", ""Tracking Shipments - PPTCO!p:p""), 0))"),"PPT-30") -> PPT-30 | D33: 2675 | E33: Kit Cat Litter KCIT230034B | F33: Kit Cat | G33: Before DSV | H33: Done | K33: Done | L33: Yes | M33: 45314 | N33: 0012024 | O33: 2 | P33: 1 | Q33: 1 | R33: 45325 | S33: =IFERROR(IF(DATEDIF(M33,R33,"d")=0,"",DATEDIF(M33,R33,"d")),"") -> 11 | Y33: Closed
A34: 33 | B34: =IFERROR(__xludf.DUMMYFUNCTION("INDEX(IMPORTRANGE(""https://docs.google.com/spreadsheets/d/1S7deMHO2waboU9dywpXeKIDfCmjiuAc0HUIsFpaXQq8/edit?gid=0#gid=0"", ""Tracking Shipments - PPTCO!o:o""), MATCH(D34, IMPORTRANGE(""https://docs.google.com/spreadsheets/d/1S7deMHO2waboU9dywpXeKIDfCmjiu"&"Ac0HUIsFpaXQq8/edit?gid=0#gid=0"", ""Tracking Shipments - PPTCO!p:p""), 0))"),"PPT-30") -> PPT-30 | D34: 2718 | E34: Kit Cat Litter KCIT230034A | F34: Kit Cat | G34: Before DSV | H34: Done | K34: Done | L34: Yes | M34: 45316 | N34: 0012024 | O34: 17 | P34: 9 | Q34: 4 | R34: 45328 | S34: =IFERROR(IF(DATEDIF(M34,R34,"d")=0,"",DATEDIF(M34,R34,"d")),"") -> 12 | Y34: Closed
A35: 34 | B35: =IFERROR(__xludf.DUMMYFUNCTION("INDEX(IMPORTRANGE(""https://docs.google.com/spreadsheets/d/1S7deMHO2waboU9dywpXeKIDfCmjiuAc0HUIsFpaXQq8/edit?gid=0#gid=0"", ""Tracking Shipments - PPTCO!o:o""), MATCH(D35, IMPORTRANGE(""https://docs.google.com/spreadsheets/d/1S7deMHO2waboU9dywpXeKIDfCmjiu"&"Ac0HUIsFpaXQq8/edit?gid=0#gid=0"", ""Tracking Shipments - PPTCO!p:p""), 0))"),"#N/A") -> #N/A | D35: 8092 | E35: KIt cat Gravy KCIT230310 | F35: Kit Cat | G35: Before DSV | H35: Done | K35: Done | L35: Yes | M35: 45316 | N35: 0012024 | O35: 23 | P35: 15 | Q35: 15 | R35: 45328 | S35: =IFERROR(IF(DATEDIF(M35,R35,"d")=0,"",DATEDIF(M35,R35,"d")),"") -> 12 | Y35: Closed
A36: 35 | B36: =IFERROR(__xludf.DUMMYFUNCTION("INDEX(IMPORTRANGE(""https://docs.google.com/spreadsheets/d/1S7deMHO2waboU9dywpXeKIDfCmjiuAc0HUIsFpaXQq8/edit?gid=0#gid=0"", ""Tracking Shipments - PPTCO!o:o""), MATCH(D36, IMPORTRANGE(""https://docs.google.com/spreadsheets/d/1S7deMHO2waboU9dywpXeKIDfCmjiu"&"Ac0HUIsFpaXQq8/edit?gid=0#gid=0"", ""Tracking Shipments - PPTCO!p:p""), 0))"),"PPT-89") -> PPT-89 | D36: 8076 | E36: Deboned&Gravy KCIT230314 | F36: Kit Cat | G36: Before DSV | H36: Done | K36: Done | L36: Yes | M36: 45319 | N36: 0012024 | O36: 18 | P36: 10 | Q36: 8 | R36: 45328 | S36: =IFERROR(IF(DATEDIF(M36,R36,"d")=0,"",DATEDIF(M36,R36,"d")),"") -> 9 | Y36: Closed
A37: 36 | B37: =IFERROR(__xludf.DUMMYFUNCTION("INDEX(IMPORTRANGE(""https://docs.google.com/spreadsheets/d/1S7deMHO2waboU9dywpXeKIDfCmjiuAc0HUIsFpaXQq8/edit?gid=0#gid=0"", ""Tracking Shipments - PPTCO!o:o""), MATCH(D37, IMPORTRANGE(""https://docs.google.com/spreadsheets/d/1S7deMHO2waboU9dywpXeKIDfCmjiu"&"Ac0HUIsFpaXQq8/edit?gid=0#gid=0"", ""Tracking Shipments - PPTCO!p:p""), 0))"),"#N/A") -> #N/A | D37: 8103 | E37: Deboned - KCIT230311 | F37: Kit Cat | G37: Before DSV | H37: Done | K37: Done | L37: Yes | M37: 45321 | N37: 0012024 | O37: 19 | P37: 11 | Q37: 9 | R37: 45328 | S37: =IFERROR(IF(DATEDIF(M37,R37,"d")=0,"",DATEDIF(M37,R37,"d")),"") -> 7 | Y37: Closed
A38: 37 | B38: =IFERROR(__xludf.DUMMYFUNCTION("INDEX(IMPORTRANGE(""https://docs.google.com/spreadsheets/d/1S7deMHO2waboU9dywpXeKIDfCmjiuAc0HUIsFpaXQq8/edit?gid=0#gid=0"", ""Tracking Shipments - PPTCO!o:o""), MATCH(D38, IMPORTRANGE(""https://docs.google.com/spreadsheets/d/1S7deMHO2waboU9dywpXeKIDfCmjiu"&"Ac0HUIsFpaXQq8/edit?gid=0#gid=0"", ""Tracking Shipments - PPTCO!p:p""), 0))"),"PPT-81") -> PPT-81 | D38: 8328 | E38: Schesir - 900006 | F38: Schesir | G38: Before DSV | H38: Done | K38: Done | L38: Yes | M38: 45321 | N38: 0012024 | O38: 6 | P38: 8 | Q38: 13 | R38: 45328 | S38: =IFERROR(IF(DATEDIF(M38,R38,"d")=0,"",DATEDIF(M38,R38,"d")),"") -> 7 | Y38: Closed
A39: 38 | B39: =IFERROR(__xludf.DUMMYFUNCTION("INDEX(IMPORTRANGE(""https://docs.google.com/spreadsheets/d/1S7deMHO2waboU9dywpXeKIDfCmjiuAc0HUIsFpaXQq8/edit?gid=0#gid=0"", ""Tracking Shipments - PPTCO!o:o""), MATCH(D39, IMPORTRANGE(""https://docs.google.com/spreadsheets/d/1S7deMHO2waboU9dywpXeKIDfCmjiu"&"Ac0HUIsFpaXQq8/edit?gid=0#gid=0"", ""Tracking Shipments - PPTCO!p:p""), 0))"),"#N/A") -> #N/A | D39: 9629 | E39: Laviosa LAT2023000001848 | F39: Laviosa | G39: Before DSV | H39: Done | K39: Done | L39: Yes | M39: 45324 | N39: 0012024 | O39: 9 | P39: 6 | Q39: 3 | R39: 45328 | S39: =IFERROR(IF(DATEDIF(M39,R39,"d")=0,"",DATEDIF(M39,R39,"d")),"") -> 4 | Y39: Closed
A40: 39 | B40: =IFERROR(__xludf.DUMMYFUNCTION("INDEX(IMPORTRANGE(""https://docs.google.com/spreadsheets/d/1S7deMHO2waboU9dywpXeKIDfCmjiuAc0HUIsFpaXQq8/edit?gid=0#gid=0"", ""Tracking Shipments - PPTCO!o:o""), MATCH(D40, IMPORTRANGE(""https://docs.google.com/spreadsheets/d/1S7deMHO2waboU9dywpXeKIDfCmjiu"&"Ac0HUIsFpaXQq8/edit?gid=0#gid=0"", ""Tracking Shipments - PPTCO!p:p""), 0))"),"PPT-41") -> PPT-41 | D40: 10947 | E40: Selim 287+288+298 | F40: Biosand | G40: Before DSV | H40: Done | K40: Done | L40: Yes | M40: 45311 | N40: 0012024 | O40: 13-14-15 | P40: 18-19-20 | Q40: 17-18-19 | R40: 45329 | S40: =IFERROR(IF(DATEDIF(M40,R40,"d")=0,"",DATEDIF(M40,R40,"d")),"") -> 18 | Y40: Closed
...

Sheet Registration Tracking Sheet
B1: Range | C1: Item Code | D1: Item Name | E1: Request Date | F1: Status | G1: Received Date | H1: Registred | I1: Number | J1: Days to be ready | K1: Remarks
A2: 1 | B2: Inaba Delights | C2: USA-868 | D2: INABA CUP DASHI DELIGHTS CHICKEN WITH SALMON RECIPE (USA-868) | E2: 45579 | F2: =VLOOKUP(D2,Sheet15!D:H,5,FALSE) -> مكتمل | H2: Yes | I2: =VLOOKUP(D2,Sheet15!D:K,8,FALSE) -> 2024-312651 | J2: =G2-E2 -> -45579 | K2: =VLOOKUP(D2,Sheet15!D:G,4,FALSE)
A3: 2 | B3: Inaba Delights | C3: USA-867 | D3: INABA CUP DASHI DELIGHT S CHICKEN WITH BONITO FLAKES RECIPE (USA-867) | E3: 45579 | F3: =VLOOKUP(D3,Sheet15!D:H,5,FALSE) -> مكتمل | H3: Yes | I3: =VLOOKUP(D3,Sheet15!D:K,8,FALSE) -> 2024-312647 | J3: =G3-E3 -> -45579 | K3: =VLOOKUP(D3,Sheet15!D:G,4,FALSE)
A4: 3 | B4: Inaba Delights | C4: USA-862 | D4: INABA CUP DASHI DELIGHTS CHICKEN WITH TUNA SALMON RECIPE (USA-862) | E4: 45579 | F4: =VLOOKUP(D4,Sheet15!D:H,5,FALSE) -> مكتمل | H4: Yes | I4: =VLOOKUP(D4,Sheet15!D:K,8,FALSE) -> 2024-312605 | J4: =G4-E4 -> -45579 | K4: =VLOOKUP(D4,Sheet15!D:G,4,FALSE)
A5: 4 | B5: Inaba Delights | C5: USA-861 | D5: INABA CUP DASHI DELIGHTS CHICKEN WITH TUNA RECIPE (USA-861) | E5: 45579 | F5: =VLOOKUP(D5,Sheet15!D:H,5,FALSE) -> مكتمل | H5: Yes | I5: =VLOOKUP(D5,Sheet15!D:K,8,FALSE) -> 2024-312585 | J5: =G5-E5 -> -45579 | K5: =VLOOKUP(D5,Sheet15!D:G,4,FALSE)
A6: 5 | B6: Inaba Delights | C6: USA-866 | D6: INABA CUP DASHI DELIGHTS CHICKEN W ITH CHEESE RECIPE (USA-866) | E6: 45579 | F6: =VLOOKUP(D6,Sheet15!D:H,5,FALSE) -> مكتمل | H6: Yes | I6: =VLOOKUP(D6,Sheet15!D:K,8,FALSE) -> 2024-312643 | J6: =G6-E6 -> -45579 | K6: =VLOOKUP(D6,Sheet15!D:G,4,FALSE)
A7: 6 | B7: Inaba Delights | C7: USA-865 | D7: INABA CUP DASHI DELIGHTS CHICKEN WITH SCALLOP RECIPE (USA-865) | E7: 45579 | F7: =VLOOKUP(D7,Sheet15!D:H,5,FALSE) -> مكتمل | H7: Yes | I7: =VLOOKUP(D7,Sheet15!D:K,8,FALSE) -> 2024-312633 | J7: =G7-E7 -> -45579 | K7: =VLOOKUP(D7,Sheet15!D:G,4,FALSE)
A8: 7 | B8: Inaba Delights | C8: USA-864 | D8: INABA CUP DASHI DELIGHTS CHICKEN RECIPE (USA-864) | E8: 45579 | F8: =VLOOKUP(D8,Sheet15!D:H,5,FALSE) -> مكتمل | H8: Yes | I8: =VLOOKUP(D8,Sheet15!D:K,8,FALSE) -> 2024-312626 | J8: =G8-E8 -> -45579 | K8: =VLOOKUP(D8,Sheet15!D:G,4,FALSE)
A9: 8 | B9: Inaba Delights | C9: USA-863 | D9: INABA CUP DASHI DELIGHTS CHICKEN WITH TUNA & SCALLOP RECIPE (USA-863) | E9: 45579 | F9: =VLOOKUP(D9,Sheet15!D:H,5,FALSE) -> مكتمل | H9: Yes | I9: =VLOOKUP(D9,Sheet15!D:K,8,FALSE) -> 2024-312617 | J9: =G9-E9 -> -45579 | K9: =VLOOKUP(D9,Sheet15!D:G,4,FALSE)
A10: 9 | B10: Wellness | C10: 10880 | D10: WEL WC CORE 98% Beef Recipe 12/85g | E10: 45581 | F10: =VLOOKUP(D10,Sheet15!D:H,5,FALSE) -> مكتمل | H10: Yes | I10: =VLOOKUP(D10,Sheet15!D:K,8,FALSE) -> 2024-346683 | J10: =G10-E10 -> -45581 | K10: =VLOOKUP(D10,Sheet15!D:G,4,FALSE)
A11: 10 | B11: Wellness | C11: 10881 | D11: WEL WC CORE 98% Turkey Recipe12/85g | E11: 45581 | F11: =VLOOKUP(D11,Sheet15!D:H,5,FALSE) -> مكتمل | H11: Yes | I11: =VLOOKUP(D11,Sheet15!D:K,8,FALSE) -> 2024-346711 | J11: =G11-E11 -> -45581 | K11: =VLOOKUP(D11,Sheet15!D:G,4,FALSE)
A12: 11 | B12: Wellness | C12: 10882 | D12: WEL WC CORE 98% Ckn/SalmRecip12/85g | E12: 45581 | F12: =VLOOKUP(D12,Sheet15!D:H,5,FALSE) -> مكتمل | H12: Yes | I12: =VLOOKUP(D12,Sheet15!D:K,8,FALSE) -> 2024-346720 | J12: =G12-E12 -> -45581 | K12: =VLOOKUP(D12,Sheet15!D:G,4,FALSE)
A13: 12 | B13: Wellness | C13: 10854 | D13: WEL WD CORE 95 Turkey with Kale 400g | E13: 45581 | F13: =VLOOKUP(D13,Sheet15!D:H,5,FALSE) -> مكتمل | H13: Yes | I13: =VLOOKUP(D13,Sheet15!D:K,8,FALSE) -> 2024-330246 | J13: =G13-E13 -> -45581 | K13: =VLOOKUP(D13,Sheet15!D:G,4,FALSE)
A14: 13 | B14: Wellness | C14: 10856 | D14: WEL WD CORE 95 Lamb With Pumpkin 400g | E14: 45581 | F14: =VLOOKUP(D14,Sheet15!D:H,5,FALSE) -> مكتمل | H14: Yes | I14: =VLOOKUP(D14,Sheet15!D:K,8,FALSE) -> 2024-330277 | J14: =G14-E14 -> -45581 | K14: =VLOOKUP(D14,Sheet15!D:G,4,FALSE)
A15: 14 | B15: Wellness | C15: 10857 | D15: WEL WD CORE 95 Beef with Broccoli 400g | E15: 45581 | F15: =VLOOKUP(D15,Sheet15!D:H,5,FALSE) -> مكتمل | H15: Yes | I15: =VLOOKUP(D15,Sheet15!D:K,8,FALSE) -> 2024-330299 | J15: =G15-E15 -> -45581 | K15: =VLOOKUP(D15,Sheet15!D:G,4,FALSE)
A16: 15 | B16: Wellness | C16: 10858 | D16: WEL WD CORE 95 Turkey with Goat 400g | E16: 45581 | F16: =VLOOKUP(D16,Sheet15!D:H,5,FALSE) -> مكتمل | H16: Yes | I16: =VLOOKUP(D16,Sheet15!D:K,8,FALSE) -> 2024-330316 | J16: =G16-E16 -> -45581 | K16: =VLOOKUP(D16,Sheet15!D:G,4,FALSE)
A17: 16 | B17: Wellness | C17: 10859 | D17: WEL WD CORE 95 Chicken with Duck with carrots 400g | E17: 45581 | F17: =VLOOKUP(D17,Sheet15!D:H,5,FALSE) -> مكتمل | H17: Yes | I17: =VLOOKUP(D17,Sheet15!D:K,8,FALSE) -> 2024-330324 | J17: =G17-E17 -> -45581 | K17: =VLOOKUP(D17,Sheet15!D:G,4,FALSE)
A18: 17 | B18: Wellness | C18: 10870 | D18: WEL WD CORE 95 Puppy original 400g | E18: 45581 | F18: =VLOOKUP(D18,Sheet15!D:H,5,FALSE) -> مكتمل | H18: Yes | I18: =VLOOKUP(D18,Sheet15!D:K,8,FALSE) -> 2024-330334 | J18: =G18-E18 -> -45581 | K18: =VLOOKUP(D18,Sheet15!D:G,4,FALSE)
A19: 18 | B19: Wellness | D19: Wellness core purely pate adult chicken | E19: 45589 | F19: =VLOOKUP(D19,Sheet15!D:H,5,FALSE) -> مكتمل | H19: Yes | I19: =VLOOKUP(D19,Sheet15!D:K,8,FALSE) -> 2024-346809 | J19: =G19-E19 -> -45589 | K19: =VLOOKUP(D19,Sheet15!D:G,4,FALSE)
A20: 19 | B20: Wellness | D20: Wellness Core Purely Pate Adult Chicken & Turkey | E20: 45589 | F20: =VLOOKUP(D20,Sheet15!D:H,5,FALSE) -> مكتمل | H20: Yes | I20: =VLOOKUP(D20,Sheet15!D:K,8,FALSE) -> 2024-346825 | J20: =G20-E20 -> -45589 | K20: =VLOOKUP(D20,Sheet15!D:G,4,FALSE)
A21: 20 | B21: Wellness | D21: Wellness core purely pate adult chicken & beef | E21: 45589 | F21: =VLOOKUP(D21,Sheet15!D:H,5,FALSE) -> مكتمل | H21: Yes | I21: =VLOOKUP(D21,Sheet15!D:K,8,FALSE) -> 2024-346831 | J21: =G21-E21 -> -45589 | K21: =VLOOKUP(D21,Sheet15!D:G,4,FALSE)
A22: 21 | B22: Wellness | D22: Wellness Core Purely Pate Adult Duck & Chicken | E22: 45589 | F22: =VLOOKUP(D22,Sheet15!D:H,5,FALSE) -> مكتمل | H22: Yes | I22: =VLOOKUP(D22,Sheet15!D:K,8,FALSE) -> 2024-346837 | J22: =G22-E22 -> -45589 | K22: =VLOOKUP(D22,Sheet15!D:G,4,FALSE)
A23: 22 | B23: Wellness | D23: Wellness core purely pate kitten chicken & Tuna | E23: 45589 | F23: =VLOOKUP(D23,Sheet15!D:H,5,FALSE) -> مكتمل | H23: Yes | I23: =VLOOKUP(D23,Sheet15!D:K,8,FALSE) -> 2024-346845 | J23: =G23-E23 -> -45589 | K23: =VLOOKUP(D23,Sheet15!D:G,4,FALSE)
A24: 23 | B24: zoulx | C24: 482774 | D24: ZOLUX CHICKEN WINGS 100G | E24: 45592 | F24: =VLOOKUP(D24,Sheet15!D:H,5,FALSE) -> مكتمل | H24: Yes | I24: =VLOOKUP(D24,Sheet15!D:K,8,FALSE) -> 2024-356398 | J24: =G24-E24 -> -45592 | K24: =VLOOKUP(D24,Sheet15!D:G,4,FALSE)
A25: 24 | B25: Wellness | D25: Wellness CORE Tender Cuts with Tuna in Savoury Gravy | E25: 45593 | F25: =VLOOKUP(D25,Sheet15!D:H,5,FALSE) -> مكتمل | H25: Yes | I25: =VLOOKUP(D25,Sheet15!D:K,8,FALSE) -> 2024-341003 | J25: =G25-E25 -> -45593 | K25: =VLOOKUP(D25,Sheet15!D:G,4,FALSE)
A26: 25 | B26: Wellness | D26: Wellness CORE Signature Selects Chunky Entree Flavoured with Beef & Boneless Chicken in Sauce | E26: 45593 | F26: =VLOOKUP(D26,Sheet15!D:H,5,FALSE) -> مكتمل | H26: Yes | I26: =VLOOKUP(D26,Sheet15!D:K,8,FALSE) -> 2024-339892 | J26: =G26-E26 -> -45593 | K26: =VLOOKUP(D26,Sheet15!D:G,4,FALSE)
A27: 26 | B27: Wellness | D27: Wellness CORE Signature Selects Flaked Skipjack Tuna with Shrimp Entree in Broth | E27: 45593 | F27: =VLOOKUP(D27,Sheet15!D:H,5,FALSE) -> مكتمل | H27: Yes | I27: =VLOOKUP(D27,Sheet15!D:K,8,FALSE) -> 2024-339955 | J27: =G27-E27 -> -45593 | K27: =VLOOKUP(D27,Sheet15!D:G,4,FALSE)
A28: 27 | B28: Wellness | D28: Wellness CORE Tender Cuts with Chicken & Salmon in Savoury Gravy | E28: 45593 | F28: =VLOOKUP(D28,Sheet15!D:H,5,FALSE) -> مكتمل | H28: Yes | I28: =VLOOKUP(D28,Sheet15!D:K,8,FALSE) -> 2024-341489 | J28: =G28-E28 -> -45593 | K28: =VLOOKUP(D28,Sheet15!D:G,4,FALSE)
A29: 28 | B29: Wellness | D29: Wellness CORE Tender Cuts with Turkey & Duck in Savoury Gravy | E29: 45593 | F29: =VLOOKUP(D29,Sheet15!D:H,5,FALSE) -> مكتمل | H29: Yes | I29: =VLOOKUP(D29,Sheet15!D:K,8,FALSE) -> 2024-341501 | J29: =G29-E29 -> -45593 | K29: =VLOOKUP(D29,Sheet15!D:G,4,FALSE)
A30: 29 | B30: Wellness | D30: Wellness CORE Signature Selects Shredded Boneless Chicken Entree Flavoured with Turkey in Sauce | E30: 45593 | F30: =VLOOKUP(D30,Sheet15!D:H,5,FALSE) -> مكتمل | H30: Yes | I30: =VLOOKUP(D30,Sheet15!D:K,8,FALSE) -> 2024-340000 | J30: =G30-E30 -> -45593 | K30: =VLOOKUP(D30,Sheet15!D:G,4,FALSE)
A31: 30 | B31: Wellness | D31: Wellness CORE Tender Cuts with Chicken & Chicken Liver in Savoury Gravy | E31: 45593 | F31: =VLOOKUP(D31,Sheet15!D:H,5,FALSE) -> مكتمل | H31: Yes | I31: =VLOOKUP(D31,Sheet15!D:K,8,FALSE) -> 2024-341523 | J31: =G31-E31 -> -45593 | K31: =VLOOKUP(D31,Sheet15!D:G,4,FALSE)
A32: 31 | B32: Wellness | D32: Wellness CORE Small Breed Savoury Medleys Flavoured with Roasted Chicken, Duck, Peas & Carrot | E32: 45593 | F32: =VLOOKUP(D32,Sheet15!D:H,5,FALSE) -> مكتمل | H32: Yes | I32: =VLOOKUP(D32,Sheet15!D:K,8,FALSE) -> 2024-343330 | J32: =G32-E32 -> -45593 | K32: =VLOOKUP(D32,Sheet15!D:G,4,FALSE)
A33: 32 | B33: Wellness | D33: Wellness CORE Small Breed Savoury Medleys Flavoured with Tender Chicken, Turkey, Carrots & Green Beans | E33: 45593 | F33: =VLOOKUP(D33,Sheet15!D:H,5,FALSE) -> مكتمل | H33: Yes | I33: =VLOOKUP(D33,Sheet15!D:K,8,FALSE) -> 2024-343359 | J33: =G33-E33 -> -45593 | K33: =VLOOKUP(D33,Sheet15!D:G,4,FALSE)
A34: 33 | B34: Wellness | D34: Wellness CORE Small Breed Savoury Medleys Flavoured with Braised Lamb, Venison, White Sweet Potatoes & CatTots | E34: 45593 | F34: =VLOOKUP(D34,Sheet15!D:H,5,FALSE) -> مكتمل | H34: Yes | I34: =VLOOKUP(D34,Sheet15!D:K,8,FALSE) -> 2024-343379 | J34: =G34-E34 -> -45593 | K34: =VLOOKUP(D34,Sheet15!D:G,4,FALSE)
A35: 34 | B35: Wellness | D35: Wellness CORE Small Breed Savoury Medleys Flavoured with Roasted Chicken, Beef, Green Beans & Red Peppers | E35: 45593 | F35: =VLOOKUP(D35,Sheet15!D:H,5,FALSE) -> مكتمل | H35: Yes | I35: =VLOOKUP(D35,Sheet15!D:K,8,FALSE) -> 2024-343410 | J35: =G35-E35 -> -45593 | K35: =VLOOKUP(D35,Sheet15!D:G,4,FALSE)
A36: 35 | B36: Wellness | D36: Wellness CORE Signature Selects Shredded Boneless Chicken Entree Flavoured with Chicken Liver in Sauce | E36: 45593 | F36: =VLOOKUP(D36,Sheet15!D:H,5,FALSE) -> مكتمل | H36: Yes | I36: =VLOOKUP(D36,Sheet15!D:K,8,FALSE) -> 2024-339974 | J36: =G36-E36 -> -45593 | K36: =VLOOKUP(D36,Sheet15!D:G,4,FALSE)
... A57: 56 | B57: kit cat | D57: Kit Cat Goatmilk Cat | E57: 45614 | F57: =VLOOKUP(D57,Sheet15!D:H,5,FALSE) -> مكتمل | H57: Yes | I57: =VLOOKUP(D57,Sheet15!D:K,8,FALSE) -> 2024-370636 | J57: =G57-E57 -> -45614 | K57: =VLOOKUP(D57,Sheet15!D:G,4,FALSE)
A58: 57 | B58: kit cat | D58: Kit Cat Goatmilk Kitten | E58: 46023 | F58: جديد | H58: Yes | I58: =VLOOKUP(D58,Sheet15!D:K,8,FALSE) -> 2024-370699 | J58: =G58-E58 -> -46023 | K58: =VLOOKUP(D58,Sheet15!D:G,4,FALSE)
A59: 58 | B59: Wellness | C59: WHZ311EU | D59: Whimzees Ricebone 540g | E59: 45614 | F59: =VLOOKUP(D59,Sheet15!D:H,5,FALSE) -> مكتمل | H59: Yes | I59: =VLOOKUP(D59,Sheet15!D:K,8,FALSE) -> 2024-371365 | J59: =G59-E59 -> -45614 | K59: =VLOOKUP(D59,Sheet15!D:G,4,FALSE)
A60: 59 | B60: Wellness | C60: WHZ316EU | D60: Whimzees Stix S 420g | E60: 45614 | F60: =VLOOKUP(D60,Sheet15!D:H,5,FALSE) -> مكتمل | H60: Yes | I60: =VLOOKUP(D60,Sheet15!D:K,8,FALSE) -> 2024-371592 | J60: =G60-E60 -> -45614 | K60: =VLOOKUP(D60,Sheet15!D:G,4,FALSE)
...

Sheet POed not arrived
A1: PPT Number | B1: Description | C1: Invoice Number | D1: PO Number
A2: PPT-288 | B2: KC 400g SOKC000819 | C2: SOKC000819 | D2: 2600044
A3: PPT-293 | B3: Applaws Dry x13 262567 262568 262569 262570 262571 262572 262573 262574 262575 262576 262577 262578 262579 | C3: 262567 262568 262569 262570 262571 262572 262573 262574 262575 262576 262577 262578 262579 | D3: 2600048->60

Sheet FDA Registration Priority
A1: brand | B1: Priority
A2: Instinct | B2: 1
A3: forza | B3: 2
A4: catidea | B4: 7
A5: bioPetActive | B5: 6
A6: josera | B6: 4
A7: zolux | B7: 3
A8: Absolute | B8: 5

Sheet Sheet1
B1: Clearance | C1: Arrived | D1: Ads | E1: PO | F1: Grr | G1: PI | H1: Review | I1: Notes | J1: Arabic Stickers
A2: Profine x3 | B2: x | C2: x | D2: x | E2: done | F2: done | G2: done
A3: Profine x2 | B3: x | E3: 273-274 | F3: 270-271 | G3: done
A4: Schesir Wet 900611 | B4: x | C4: x | D4: x | E4: 267 | F4: 264 | G4: done
A5: Schesir Wet 900609 | B5: x | C5: x | D5: x | E5: 266 | F5: 266 | G5: done
A6: KCIT220052A 10L x8 | B6: x | C6: x | D6: x | E6: 259 | F6: 261 | G6: done
A7: Zolux Rodywood | B7: x | C7: x | D7: x | E7: 260 - 261 | F7: 258-259 | G7: done
A8: Zolux Annah | B8: x | C8: x | E8: 269 | F8: 268 | G8: done
A9: MPS 357 | B9: x | C9: x | E9: 265 | F9: 265 | G9: done
A10: KCIT220102 Soya | B10: x | C10: x | D10: x | E10: 258 | F10: 257 | G10: done
A11: Applaws x2 228152 - 228153 | B11: x | C11: x | E11: 263-264 | F11: 262-263 | G11: done
A12: MPS 293 | B12: x | C12: x | E12: 262 | F12: 260 | G12: done
A13: Whitebridge | B13: x | C13: x | D13: x | E13: 277 | F13: 272
A14: MC | B14: x | C14: x | D14: x | E14: 285
A15: Zolux Rody.3 | B15: x | C15: x | D15: x | E15: 276 | F15: 275
A16: Nestle 9304235626 | B16: x | C16: x | D16: x | E16: 268 | F16: x
A17: Nestle 9304235820 | B17: x | C17: x | E17: 270 | F17: 276
A18: MPS404 | B18: x | C18: x | E18: 271 | F18: 269
A19: Kitcat Litter 10L x7 | B19: x | C19: x | E19: 272 | F19: 273
A20: KCIT220053C | B20: x | C20: x | D20: x | E20: 275 | F20: 274
A21: Zolux Tunisia 833520 | B21: x | C21: x | E21: 286 | F21: 282 | H21: تدخيل عالسستم
A22: Zolux Shenzen 837260 | B22: x | C22: x | D22: x | E22: 279 | F22: 281
A23: Nestle 9304236412 | B23: x | C23: x | E23: 280
A24: Nestle 9304235917 | B24: x | C24: x | E24: 278 | F24: 277
A25: Biosand 109/111/112 | B25: x | C25: x | H25: New itm
A26: Beaphar 2022S20613 | B26: x | C26: x | E26: 284
A27: Applaws Dry 229916+228713 | B27: x | C27: x | E27: 282-283 | F27: 279
A28: Nestle 9304236423 | B28: x | C28: x | E28: 281 | F28: 280
A29: Zolux Nantong 831605 | B29: x | C29: x | E29: x | F29: x | H29: تدخيل عالسستم
A30: Applaws 228154, 228155, 228157, 228714
A31: KCIT21011 | B31: x | C31: x | E31: 294
A32: LindoCat *3 - 2300000288 - 2300000283 - 2100002082 | B32: x | C32: x
A33: Sanal 5220366 | B33: x | C33: x | E33: 295 | F33: x | G33: x
A34: MPS 477 | B34: x | C34: x | D34: x | E34: x | F34: x | G34: x
A35: MPS 492 | B35: x | C35: x | D35: x | E35: x | F35: x | G35: x
A36: Zolux - China Rody.3 3442+ 3443 | B36: x | C36: x | E36: x | F36: x | G36: x
A37: LindoCat x3 - 2300000267 - 2300000271 - 2300000272 | B37: x | C37: x | D37: x | E37: x | F37: x | G37: x
A38: Schesir Wet 502098 7th 900608 | B38: x | C38: x | D38: x | E38: x | F38: x | G38: x
A39: Schesir Wet 502098 9th 900610 | B39: x | C39: x | D39: x | E39: x | F39: x | G39: x
A40: Schesir order 502175 - 2nd container 900670 | B40: x | C40: x | D40: x | E40: x | F40: x | G40: x
...

Sheet Dashboard
A1: ='Arrived Shipments'!F2 -> Josera | B1: ='Arrived Shipments'!M2 -> 45225 | C1: ='Arrived Shipments'!R2 -> SMACC | D1: ='Arrived Shipments'!S2 | E1: {=UNIQUE(A1:A296)} -> Josera | F1: =COUNTIF(A1:A244,E1) -> 23 | G1: =COUNTA(B:B) -> 343 | H1: =COUNTA(C:C) -> 342 | I1: =H1/G1 -> 0.99708455 | J1: =K1-I1 -> 0.0029154519 | K1: 1
A2: ='Arrived Shipments'!F3 -> Kit Cat | B2: ='Arrived Shipments'!M3 -> 45236 | C2: ='Arrived Shipments'!R3 -> SMACC | D2: ='Arrived Shipments'!S3 | E2: Kit Cat | F2: =COUNTIF(A2:A245,E2) -> 44 | G2: =COUNTIFS(B1:B1000, ">=" & EDATE(TODAY(), -3), B1:B1000, "<=" & TODAY()) -> 0 | H2: =COUNTIFS(B1:B1000, ">=" & EDATE(TODAY(), -3), B1:B1000, "<=" & TODAY(), C1:C1000, "<>") -> 0 | I2: =H2/G2 -> #DIV/0! | J2: =K2-I2 -> #DIV/0! | K2: 1
A3: ='Arrived Shipments'!F4 -> Laroy | B3: ='Arrived Shipments'!M4 -> 45229 | C3: ='Arrived Shipments'!R4 -> SMACC | D3: ='Arrived Shipments'!S4 | E3: Laroy | F3: =COUNTIF(A3:A246,E3) -> 20 | J3: =AVERAGE(D:D) -> 14.568905
A4: ='Arrived Shipments'!F5 -> Kit Cat | B4: ='Arrived Shipments'!M5 -> 45200 | C4: ='Arrived Shipments'!R5 -> SMACC | D4: ='Arrived Shipments'!S5 | E4: Schesir | F4: =COUNTIF(A4:A247,E4) -> 20 | J4: =COUNTIF(D:D,"<8") -> 139 | K4: =COUNTIF(D:D,">7") -> 144
A5: ='Arrived Shipments'!F6 -> Schesir | B5: ='Arrived Shipments'!M6 -> 45225 | C5: ='Arrived Shipments'!R6 -> SMACC | D5: ='Arrived Shipments'!S6 | E5: Inner Mongolia | F5: =COUNTIF(A5:A248,E5) -> 5 | H5: =J4/K4 -> 0.96527778 | I5: =K5-H5 -> 0.034722222 | K5: 1
A6: ='Arrived Shipments'!F7 -> Schesir | B6: ='Arrived Shipments'!M7 -> 45225 | C6: ='Arrived Shipments'!R7 -> SMACC | D6: ='Arrived Shipments'!S7 | E6: INABA | F6: =COUNTIF(A6:A249,E6) -> 5
A7: ='Arrived Shipments'!F8 -> Laroy | B7: ='Arrived Shipments'!M8 -> 45241 | C7: ='Arrived Shipments'!R8 -> SMACC | D7: ='Arrived Shipments'!S8 | E7: Sanal | F7: =COUNTIF(A7:A250,E7) -> 6
A8: ='Arrived Shipments'!F9 -> Inner Mongolia | B8: ='Arrived Shipments'!M9 -> 45238 | C8: ='Arrived Shipments'!R9 -> SMACC | D8: ='Arrived Shipments'!S9 | E8: Butchers | F8: =COUNTIF(A8:A251,E8) -> 12
A9: ='Arrived Shipments'!F10 -> Kit Cat | B9: ='Arrived Shipments'!M10 -> 45241 | C9: ='Arrived Shipments'!R10 -> SMACC | D9: ='Arrived Shipments'!S10 | E9: Applaws | F9: =COUNTIF(A9:A252,E9) -> 20
A10: ='Arrived Shipments'!F11 -> INABA | B10: ='Arrived Shipments'!M11 -> 45270 | C10: ='Arrived Shipments'!R11 -> SMACC | D10: ='Arrived Shipments'!S11 | E10: CatIdea | F10: =COUNTIF(A10:A253,E10) -> 1
A11: ='Arrived Shipments'!F12 -> Sanal | B11: ='Arrived Shipments'!M12 -> 45265 | C11: ='Arrived Shipments'!R12 -> SMACC | D11: ='Arrived Shipments'!S12 | E11: MyFamily | F11: =COUNTIF(A11:A254,E11) -> 2
A12: ='Arrived Shipments'!F13 -> Schesir | B12: ='Arrived Shipments'!M13 -> 45248 | C12: ='Arrived Shipments'!R13 -> SMACC | D12: ='Arrived Shipments'!S13 | E12: Versele Laga
A13: ='Arrived Shipments'!F14 -> Schesir | B13: ='Arrived Shipments'!M14 -> 44907 | C13: ='Arrived Shipments'!R14 -> SMACC | D13: ='Arrived Shipments'!S14 | E13: Laviosa | F13: =COUNTIF(A13:A256,E13) -> 18
A14: ='Arrived Shipments'!F15 -> Laroy | B14: ='Arrived Shipments'!M15 -> 45270 | C14: ='Arrived Shipments'!R15 -> SMACC | D14: ='Arrived Shipments'!S15 | E14: Biosand | F14: =COUNTIF(A14:A257,E14) -> 5
A15: ='Arrived Shipments'!F16 -> Butchers | B15: ='Arrived Shipments'!M16 -> 45273 | C15: ='Arrived Shipments'!R16 -> SMACC | D15: ='Arrived Shipments'!S16 | E15: Princess | F15: =COUNTIF(A15:A258,E15) -> 3
A16: ='Arrived Shipments'!F17 -> Kit Cat | B16: ='Arrived Shipments'!M17 -> 45281 | C16: ='Arrived Shipments'!R17 -> SMACC | D16: ='Arrived Shipments'!S17 | F16: =COUNTIF(A16:A259,E16) -> 0
A17: ='Arrived Shipments'!F18 -> Kit Cat | B17: ='Arrived Shipments'!M18 -> 45280 | C17: ='Arrived Shipments'!R18 -> SMACC | D17: ='Arrived Shipments'!S18 | E17: Dr.Clauder | F17: =COUNTIF(A17:A260,E17) -> 5
A18: ='Arrived Shipments'!F19 -> Butchers | B18: ='Arrived Shipments'!M19 -> 45273 | C18: ='Arrived Shipments'!R19 -> SMACC | D18: ='Arrived Shipments'!S19 | E18: Beaphar | F18: =COUNTIF(A18:A261,E18) -> 3
A19: ='Arrived Shipments'!F20 -> Kit Cat | B19: ='Arrived Shipments'!M20 -> 45293 | C19: ='Arrived Shipments'!R20 -> SMACC | D19: ='Arrived Shipments'!S20 | E19: Codico | F19: =COUNTIF(A19:A262,E19) -> 3
A20: ='Arrived Shipments'!F21 -> Kit Cat | B20: ='Arrived Shipments'!M21 -> 45293 | C20: ='Arrived Shipments'!R21 -> SMACC | D20: ='Arrived Shipments'!S21 | E20: Zolux | F20: =COUNTIF(A20:A263,E20) -> 12
A21: ='Arrived Shipments'!F22 -> Applaws | B21: ='Arrived Shipments'!M22 -> 45278 | C21: ='Arrived Shipments'!R22 -> SMACC | D21: ='Arrived Shipments'!S22 | E21: HEALTH & HAPPINESS | F21: =COUNTIF(A21:A264,E21) -> 5
A22: ='Arrived Shipments'!F23 -> Applaws | B22: ='Arrived Shipments'!M23 -> 45291 | C22: ='Arrived Shipments'!R23 -> SMACC | D22: ='Arrived Shipments'!S23 | E22: Dubex | F22: =COUNTIF(A22:A265,E22) -> 2
A23: ='Arrived Shipments'!F24 -> CatIdea | B23: ='Arrived Shipments'!M24 -> 45300 | C23: ='Arrived Shipments'!R24 -> 45328 | D23: ='Arrived Shipments'!S24 -> 28 | E23: MPS | F23: =COUNTIF(A23:A266,E23) -> 5
A24: ='Arrived Shipments'!F25 -> MyFamily | B24: ='Arrived Shipments'!M25 -> 45277 | C24: ='Arrived Shipments'!R25 -> SMACC | D24: ='Arrived Shipments'!S25 | E24: Dairy Pet | F24: =COUNTIF(A24:A267,E24) -> 1
A25: ='Arrived Shipments'!F26 -> Laroy | B25: ='Arrived Shipments'!M26 | C25: ='Arrived Shipments'!R26 | D25: ='Arrived Shipments'!S26 | E25: zupreem | F25: =COUNTIF(A25:A268,E25) -> 3
A26: ='Arrived Shipments'!F27 -> Kit Cat | B26: ='Arrived Shipments'!M27 -> 45302 | C26: ='Arrived Shipments'!R27 -> 45328 | D26: ='Arrived Shipments'!S27 -> 26 | E26: MPB | F26: =COUNTIF(A26:A269,E26) -> 1
A27: ='Arrived Shipments'!F28 -> Versele Laga | B27: ='Arrived Shipments'!M28 -> 45325 | C27: ='Arrived Shipments'!R28 -> 45329 | D27: ='Arrived Shipments'!S28 -> 4 | E27: Nasta | F27: =COUNTIF(A27:A270,E27) -> 1
A28: ='Arrived Shipments'!F29 -> Versele Laga | B28: ='Arrived Shipments'!M29 -> 45325 | C28: ='Arrived Shipments'!R29 -> 45329 | D28: ='Arrived Shipments'!S29 -> 4 | E28: Stefanplast | F28: =COUNTIF(A28:A271,E28) -> 1
... A37: ='Arrived Shipments'!F38 -> Schesir | B37: ='Arrived Shipments'!M38 -> 45321 | C37: ='Arrived Shipments'!R38 -> 45328 | D37: ='Arrived Shipments'!S38 -> 7 | E37: Felyn Go | F37: =COUNTIF(A37:A280,E37) -> 1
A38: ='Arrived Shipments'!F39 -> Laviosa | B38: ='Arrived Shipments'!M39 -> 45324 | C38: ='Arrived Shipments'!R39 -> 45328 | D38: ='Arrived Shipments'!S39 -> 4 | F38: =COUNTIF(A38:A281,E38) -> 0
A39: ='Arrived Shipments'!F40 -> Biosand | B39: ='Arrived Shipments'!M40 -> 45311 | C39: ='Arrived Shipments'!R40 -> 45329 | D39: ='Arrived Shipments'!S40 -> 18 | F39: =COUNTIF(A39:A282,E39) -> 0
A40: ='Arrived Shipments'!F41 -> Schesir | B40: ='Arrived Shipments'!M41 -> 45321 | C40: ='Arrived Shipments'!R41 -> 45329 | D40: ='Arrived Shipments'!S41 -> 8 | F40: =COUNTIF(A40:A283,E40) -> 0
A41: ='Arrived Shipments'!F42 -> INABA | B41: ='Arrived Shipments'!M42 -> 45321 | C41: ='Arrived Shipments'!R42 -> 45329 | D41: ='Arrived Shipments'!S42 -> 8 | F41: =COUNTIF(A41:A284,E41) -> 0
A42: ='Arrived Shipments'!F43 -> Kit Cat | B42: ='Arrived Shipments'!M43 -> 45330 | C42: ='Arrived Shipments'!R43 -> 45333 | D42: ='Arrived Shipments'!S43 -> 3 | F42: =COUNTIF(A42:A285,E42) -> 0
A43: ='Arrived Shipments'!F44 -> Kit Cat | B43: ='Arrived Shipments'!M44 -> 45329 | C43: ='Arrived Shipments'!R44 -> 45333 | D43: ='Arrived Shipments'!S44 -> 4 | F43: =COUNTIF(A43:A286,E43) -> 0
A44: ='Arrived Shipments'!F45 -> Schesir | B44: ='Arrived Shipments'!M45 -> 45335 | C44: ='Arrived Shipments'!R45 -> 45336 | D44: ='Arrived Shipments'!S45 -> 1 | F44: =COUNTIF(A44:A287,E44) -> 0
A45: ='Arrived Shipments'!F46 -> Schesir | B45: ='Arrived Shipments'!M46 -> 45307 | C45: ='Arrived Shipments'!R46 -> 45361 | D45: ='Arrived Shipments'!S46 -> 54 | F45: =COUNTIF(A45:A288,E45) -> 0
A46: ='Arrived Shipments'!F47 -> Schesir | B46: ='Arrived Shipments'!M47 -> 45308 | C46: ='Arrived Shipments'!R47 -> 45360 | D46: ='Arrived Shipments'!S47 -> 52 | F46: =COUNTIF(A46:A289,E46) -> 0
A47: ='Arrived Shipments'!F48 -> Applaws | B47: ='Arrived Shipments'!M48 -> 45353 | C47: ='Arrived Shipments'!R48 -> 45357 | D47: ='Arrived Shipments'!S48 -> 4 | F47: =COUNTIF(A47:A290,E47) -> 0
A48: ='Arrived Shipments'!F49 -> Sanal | B48: ='Arrived Shipments'!M49 -> 45353 | C48: ='Arrived Shipments'!R49 -> 45361 | D48: ='Arrived Shipments'!S49 -> 8 | F48: =COUNTIF(A48:A291,E48) -> 0
...

Sheet Saud
A1: =IFERROR(__xludf.DUMMYFUNCTION("IMPORTRANGE(""https://docs.google.com/spreadsheets/d/1Xa44tXRk3vht04Hc9meui-dd7ZRS0F6gZUdCCapKJ5E/edit?gid=1471429910#gid=1471429910"",""2024!A1:Z20000"")")," ") | B1: =IFERROR(__xludf.DUMMYFUNCTION("""COMPUTED_VALUE"""),"Vendor Code") -> Vendor Code | C1: =IFERROR(__xludf.DUMMYFUNCTION("""COMPUTED_VALUE"""),"Reference number") -> Reference number | E1: =IFERROR(__xludf.DUMMYFUNCTION("""COMPUTED_VALUE"""),"Status") -> Status | F1: =IFERROR(__xludf.DUMMYFUNCTION("""COMPUTED_VALUE"""),"Description") -> Description | G1: =IFERROR(__xludf.DUMMYFUNCTION("""COMPUTED_VALUE"""),"NAME AR") -> NAME AR | H1: =IFERROR(__xludf.DUMMYFUNCTION("""COMPUTED_VALUE"""),"Product Registration") -> Product Registration | J1: =IFERROR(__xludf.DUMMYFUNCTION("""COMPUTED_VALUE"""),"EXPIRY DATE ") -> EXPIRY DATE | L1: =IFERROR(__xludf.DUMMYFUNCTION("""COMPUTED_VALUE"""),"Vendor Code") -> Vendor Code
A2: =IFERROR(__xludf.DUMMYFUNCTION("""COMPUTED_VALUE"""),1.0) -> 1 | B2: =IFERROR(__xludf.DUMMYFUNCTION("""COMPUTED_VALUE""")," ") | C2: =IFERROR(__xludf.DUMMYFUNCTION("""COMPUTED_VALUE"""),"P-1-N-180820-2290") -> P-1-N-180820-2290 | E2: =IFERROR(__xludf.DUMMYFUNCTION("""COMPUTED_VALUE"""),"REJECTED") -> REJECTED | F2: =IFERROR(__xludf.DUMMYFUNCTION("""COMPUTED_VALUE"""),"Butcher's Natural & Healthy Dog with Chicken and Rice Pate 390g") -> Butcher's Natural & Healthy Dog with Chicken and Rice Pate 390g | G2: =IFERROR(__xludf.DUMMYFUNCTION("""COMPUTED_VALUE"""),"بوتشرز طبيعي وصحي للكلاب مع الدجاج والرز باتي 390 جم") -> بوتشرز طبيعي وصحي للكلاب مع الدجاج والرز باتي 390 جم | K2: =IFERROR(__xludf.DUMMYFUNCTION("""COMPUTED_VALUE"""),"بوتشرز بت كير ال تي دي") -> بوتشرز بت كير ال تي دي | L2: =IFERROR(__xludf.DUMMYFUNCTION("""COMPUTED_VALUE"""),"B1104") -> B1104
A3: =IFERROR(__xludf.DUMMYFUNCTION("""COMPUTED_VALUE"""),2.0) -> 2 | B3: =IFERROR(__xludf.DUMMYFUNCTION("""COMPUTED_VALUE"""),"B1107") -> B1107 | C3: =IFERROR(__xludf.DUMMYFUNCTION("""COMPUTED_VALUE"""),"P-1-N-180820-2291") -> P-1-N-180820-2291 | E3: =IFERROR(__xludf.DUMMYFUNCTION("""COMPUTED_VALUE"""),"REJECTED") -> REJECTED | F3: =IFERROR(__xludf.DUMMYFUNCTION("""COMPUTED_VALUE"""),"Butcher's Natural & Healthy Dog with Beef and Rice Pate 390g") -> Butcher's Natural & Healthy Dog with Beef and Rice Pate 390g | G3: =IFERROR(__xludf.DUMMYFUNCTION("""COMPUTED_VALUE"""),"بوتشرز طبيعي وصحي للكلاب مع لحم البقر والرز باتي 390 جم") -> بوتشرز طبيعي وصحي للكلاب مع لحم البقر والرز باتي 390 جم | K3: =IFERROR(__xludf.DUMMYFUNCTION("""COMPUTED_VALUE"""),"Factory") -> Factory | L3: =IFERROR(__xludf.DUMMYFUNCTION("""COMPUTED_VALUE"""),"B1107") -> B1107
A4: =IFERROR(__xludf.DUMMYFUNCTION("""COMPUTED_VALUE"""),3.0) -> 3 | B4: =IFERROR(__xludf.DUMMYFUNCTION("""COMPUTED_VALUE"""),"B1110") -> B1110 | C4: =IFERROR(__xludf.DUMMYFUNCTION("""COMPUTED_VALUE"""),"P-1-N-180820-2292") -> P-1-N-180820-2292 | E4: =IFERROR(__xludf.DUMMYFUNCTION("""COMPUTED_VALUE"""),"REJECTED") -> REJECTED | F4: =IFERROR(__xludf.DUMMYFUNCTION("""COMPUTED_VALUE"""),"Butcher's Natural & Healthy Dog with Lamb and Rice Pate 390g") -> Butcher's Natural & Healthy Dog with Lamb and Rice Pate 390g | G4: =IFERROR(__xludf.DUMMYFUNCTION("""COMPUTED_VALUE"""),"بوتشرز طبيعي وصحي للكلاب مع لحم ضأن والرز باتي 390 جم") -> بوتشرز طبيعي وصحي للكلاب مع لحم ضأن والرز باتي 390 جم | K4: =IFERROR(__xludf.DUMMYFUNCTION("""COMPUTED_VALUE"""),"بوتشرز بت كير ال تي دي") -> بوتشرز بت كير ال تي دي | L4: =IFERROR(__xludf.DUMMYFUNCTION("""COMPUTED_VALUE"""),"B1110") -> B1110
A5: =IFERROR(__xludf.DUMMYFUNCTION("""COMPUTED_VALUE"""),4.0) -> 4 | B5: =IFERROR(__xludf.DUMMYFUNCTION("""COMPUTED_VALUE"""),"SC1571") -> SC1571 | C5: =IFERROR(__xludf.DUMMYFUNCTION("""COMPUTED_VALUE"""),"P-1-N-190820-2298") -> P-1-N-190820-2298 | E5: =IFERROR(__xludf.DUMMYFUNCTION("""COMPUTED_VALUE"""),"تمت طباعة الشهادة") -> تمت طباعة الشهادة | F5: =IFERROR(__xludf.DUMMYFUNCTION("""COMPUTED_VALUE"""),"Sanal Anti-Hairball Bites Malt 75g") -> Sanal Anti-Hairball Bites Malt 75g | G5: =IFERROR(__xludf.DUMMYFUNCTION("""COMPUTED_VALUE"""),"سانال قطع مكافحة كرة الشعر الشعير 75 جم") -> سانال قطع مكافحة كرة الشعر الشعير 75 جم | H5: =IFERROR(__xludf.DUMMYFUNCTION("""COMPUTED_VALUE"""),"MAFE2020940") -> MAFE2020940 | K5: =IFERROR(__xludf.DUMMYFUNCTION("""COMPUTED_VALUE"""),"نيدرما بي في") -> نيدرما بي في | L5: =IFERROR(__xludf.DUMMYFUNCTION("""COMPUTED_VALUE"""),"SC1571") -> SC1571
A6: =IFERROR(__xludf.DUMMYFUNCTION("""COMPUTED_VALUE"""),5.0) -> 5 | B6: =IFERROR(__xludf.DUMMYFUNCTION("""COMPUTED_VALUE"""),"SC1572") -> SC1572 | C6: =IFERROR(__xludf.DUMMYFUNCTION("""COMPUTED_VALUE"""),"P-1-N-190820-2300") -> P-1-N-190820-2300 | E6: =IFERROR(__xludf.DUMMYFUNCTION("""COMPUTED_VALUE"""),"تمت طباعة الشهادة") -> تمت طباعة الشهادة | F6: =IFERROR(__xludf.DUMMYFUNCTION("""COMPUTED_VALUE"""),"Sanal Cheese Bites 75g") -> Sanal Cheese Bites 75g | G6: =IFERROR(__xludf.DUMMYFUNCTION("""COMPUTED_VALUE"""),"سانال قطع الجبن 75 جم") -> سانال قطع الجبن 75 جم | H6: =IFERROR(__xludf.DUMMYFUNCTION("""COMPUTED_VALUE"""),"MAFE2020939") -> MAFE2020939 | K6: =IFERROR(__xludf.DUMMYFUNCTION("""COMPUTED_VALUE"""),"نيدرما بي في") -> نيدرما بي في | L6: =IFERROR(__xludf.DUMMYFUNCTION("""COMPUTED_VALUE"""),"SC1572") -> SC1572
A7: =IFERROR(__xludf.DUMMYFUNCTION("""COMPUTED_VALUE"""),6.0) -> 6 | B7: =IFERROR(__xludf.DUMMYFUNCTION("""COMPUTED_VALUE"""),"SC1573") -> SC1573 | C7: =IFERROR(__xludf.DUMMYFUNCTION("""COMPUTED_VALUE"""),"P-1-N-200820-2316") -> P-1-N-200820-2316 | E7: =IFERROR(__xludf.DUMMYFUNCTION("""COMPUTED_VALUE"""),"تمت طباعة الشهادة") -> تمت طباعة الشهادة | F7: =IFERROR(__xludf.DUMMYFUNCTION("""COMPUTED_VALUE"""),"Sanal Denta’s 75g") -> Sanal Denta’s 75g | G7: =IFERROR(__xludf.DUMMYFUNCTION("""COMPUTED_VALUE"""),"سانال دنتاس 75 جم") -> سانال دنتاس 75 جم | H7: =IFERROR(__xludf.DUMMYFUNCTION("""COMPUTED_VALUE"""),"MAFE2020963") -> MAFE2020963 | K7: =IFERROR(__xludf.DUMMYFUNCTION("""COMPUTED_VALUE"""),"نيدرما بي في") -> نيدرما بي في | L7: =IFERROR(__xludf.DUMMYFUNCTION("""COMPUTED_VALUE"""),"SC1573") -> SC1573
A8: =IFERROR(__xludf.DUMMYFUNCTION("""COMPUTED_VALUE"""),7.0) -> 7 | B8: =IFERROR(__xludf.DUMMYFUNCTION("""COMPUTED_VALUE"""),"SC1574") -> SC1574 | C8: =IFERROR(__xludf.DUMMYFUNCTION("""COMPUTED_VALUE"""),"P-1-N-200820-2318") -> P-1-N-200820-2318 | E8: =IFERROR(__xludf.DUMMYFUNCTION("""COMPUTED_VALUE"""),"تمت طباعة الشهادة") -> تمت طباعة الشهادة | F8: =IFERROR(__xludf.DUMMYFUNCTION("""COMPUTED_VALUE"""),"Sanal Fish Bites 75g") -> Sanal Fish Bites 75g | G8: =IFERROR(__xludf.DUMMYFUNCTION("""COMPUTED_VALUE"""),"سانال قطع السمك 75 جم") -> سانال قطع السمك 75 جم | H8: =IFERROR(__xludf.DUMMYFUNCTION("""COMPUTED_VALUE"""),"MAFE2020961") -> MAFE2020961 | K8: =IFERROR(__xludf.DUMMYFUNCTION("""COMPUTED_VALUE"""),"نيدرما بي في") -> نيدرما بي في | L8: =IFERROR(__xludf.DUMMYFUNCTION("""COMPUTED_VALUE"""),"SC1574") -> SC1574
A9: =IFERROR(__xludf.DUMMYFUNCTION("""COMPUTED_VALUE"""),8.0) -> 8 | B9: =IFERROR(__xludf.DUMMYFUNCTION("""COMPUTED_VALUE"""),"SC1577") -> SC1577 | C9: =IFERROR(__xludf.DUMMYFUNCTION("""COMPUTED_VALUE"""),"P-1-N-200820-2319") -> P-1-N-200820-2319 | E9: =IFERROR(__xludf.DUMMYFUNCTION("""COMPUTED_VALUE"""),"تمت طباعة الشهادة") -> تمت طباعة الشهادة | F9: =IFERROR(__xludf.DUMMYFUNCTION("""COMPUTED_VALUE"""),"Sanal Fiesta 75g") -> Sanal Fiesta 75g | G9: =IFERROR(__xludf.DUMMYFUNCTION("""COMPUTED_VALUE"""),"سانال فييستا 75 جم") -> سانال فييستا 75 جم | H9: =IFERROR(__xludf.DUMMYFUNCTION("""COMPUTED_VALUE"""),"MAFE2020960") -> MAFE2020960 | K9: =IFERROR(__xludf.DUMMYFUNCTION("""COMPUTED_VALUE"""),"نيدرما بي في") -> نيدرما بي في | L9: =IFERROR(__xludf.DUMMYFUNCTION("""COMPUTED_VALUE"""),"SC1577") -> SC1577
A10: =IFERROR(__xludf.DUMMYFUNCTION("""COMPUTED_VALUE"""),9.0) -> 9 | B10: =IFERROR(__xludf.DUMMYFUNCTION("""COMPUTED_VALUE"""),"SC1578") -> SC1578 | C10: =IFERROR(__xludf.DUMMYFUNCTION("""COMPUTED_VALUE"""),"P-1-N-200820-2321") -> P-1-N-200820-2321 | E10: =IFERROR(__xludf.DUMMYFUNCTION("""COMPUTED_VALUE"""),"تمت طباعة الشهادة") -> تمت طباعة الشهادة | F10: =IFERROR(__xludf.DUMMYFUNCTION("""COMPUTED_VALUE"""),"Sanal Cranberry & Chicken Bites 75g") -> Sanal Cranberry & Chicken Bites 75g | G10: =IFERROR(__xludf.DUMMYFUNCTION("""COMPUTED_VALUE"""),"سانال قطع التوت البري والدجاج 75 جم") -> سانال قطع التوت البري والدجاج 75 جم | H10: =IFERROR(__xludf.DUMMYFUNCTION("""COMPUTED_VALUE"""),"MAFE2020959") -> MAFE2020959 | K10: =IFERROR(__xludf.DUMMYFUNCTION("""COMPUTED_VALUE"""),"نيدرما بي في") -> نيدرما بي في | L10: =IFERROR(__xludf.DUMMYFUNCTION("""COMPUTED_VALUE"""),"SC1578") -> SC1578
A11: =IFERROR(__xludf.DUMMYFUNCTION("""COMPUTED_VALUE"""),10.0) -> 10 | B11: =IFERROR(__xludf.DUMMYFUNCTION("""COMPUTED_VALUE"""),"421171") -> 421171 | C11: =IFERROR(__xludf.DUMMYFUNCTION("""COMPUTED_VALUE"""),"P-1-N-220820-2331") -> P-1-N-220820-2331 | E11: =IFERROR(__xludf.DUMMYFUNCTION("""COMPUTED_VALUE"""),"تمت طباعة الشهادة") -> تمت طباعة الشهادة | F11: =IFERROR(__xludf.DUMMYFUNCTION("""COMPUTED_VALUE"""),"Prestige Premium Canary 800 G") -> Prestige Premium Canary 800 G | G11: =IFERROR(__xludf.DUMMYFUNCTION("""COMPUTED_VALUE"""),"برستيج بريميوم كناري 800 جرام") -> برستيج بريميوم كناري 800 جرام | H11: =IFERROR(__xludf.DUMMYFUNCTION("""COMPUTED_VALUE"""),"MAFE2020969") -> MAFE2020969 | K11: =IFERROR(__xludf.DUMMYFUNCTION("""COMPUTED_VALUE"""),"فيرسل لاقا ان في") -> فيرسل لاقا ان في | L11: =IFERROR(__xludf.DUMMYFUNCTION("""COMPUTED_VALUE"""),"421171") -> 421171
